<mujoco model="walker2d">
  <compiler angle="degree" coordinate="global" inertiafromgeom="true"/>
  <default>
    <joint armature="0.01" damping=".1" limited="true"/>
    <geom conaffinity="0" condim="3" contype="1" density="1000" friction="0.1 .1 .1" rgba="0.8 0.6 .4 1"/>
  </default>
  <option integrator="RK4" timestep="0.002"/>
  <worldbody>
    <!-- CHANGES: see hopper.xml -->
    <!-- upper body-->
    
    <!-- lower body -->
    <body name="torso">
      <joint armature="0" axis="1 0 0" damping="0" limited="false" name="ignorex" pos="0 0 0" stiffness="0" type="slide"/>
      <joint armature="0" axis="0 0 1" damping="0" limited="false" name="ignorez" pos="0 0 0" ref="1.25" stiffness="0" type="slide"/>
      <joint armature="0" axis="0 1 0" damping="0" limited="false" name="ignorey" pos="0 0 0" stiffness="0" type="hinge"/>
      <body name="head">
        <joint armature="0" axis="0 1 0" damping="1" limited="false" name="head_joint" pos="0 0 1.70" ref="1.25" stiffness="1" type="fixed"/>
        <geom fromto="0 0 1.70 0 0 1.80" name="head_geom" size="0.09" type="capsule" mass="0.0001"/>
      </body>

      <body name="arm">
        <joint armature="0" axis="0 1 0" damping="1" range="-160 45" name="arm_joint" pos="0 0 1.70" ref="1.25" stiffness="1" type="hinge"/>
        <geom fromto="0 0 1.70 0 0 1.25" name="arm_geom" size="0.05" type="capsule"/>
        <body name="forearm">
          <joint armature="0" axis="0 1 0" damping="1" range="-135 0" name="forearm_joint" pos="0 0 1.25" ref="1.25" stiffness="1" type="hinge"/>
          <geom fromto="0 0 1.25 0 0 0.75" name="forearm_geom" size="0.05" type="capsule"/>
          <body name="hand">
            <joint armature="0" axis="0 1 0" damping="1" range="0 45" name="hand_joint" pos="0 0 0.75" ref="1.25" stiffness="1" type="fixed"/>
            <geom fromto="0 0 0.75 0 0 0.70" name="hand_geom" size="0.05" type="capsule"/>
          </body>
        </body>
      </body>
      <body name="arm_left">
        <joint armature="0" axis="0 1 0" damping="1" range="-160 45" name="arm_left_joint" pos="0 0 1.70" ref="1.25" stiffness="1" type="hinge"/>
        <geom fromto="0 0 1.70 0 0 1.25" name="arm_left_geom" rgba=".7 .3 .6 1" size="0.05" type="capsule"/>
        <body name="forearm_left">
          <joint armature="0" axis="0 1 0" damping="1" range="-135 0" name="forearm_left_joint" pos="0 0 1.25" ref="1.25" stiffness="1" type="hinge"/>
          <geom fromto="0 0 1.25 0 0 0.75" name="forearm_left_geom" rgba=".7 .3 .6 1" size="0.05" type="capsule"/>
          <body name="hand_left">
            <joint armature="0" axis="0 1 0" damping="1" range="0 45" name="hand_left_joint" pos="0 0 0.75" ref="1.25" stiffness="1" type="fixed"/>
            <geom fromto="0 0 0.75 0 0 0.70" name="hand_left_geom" rgba=".7 .3 .6 1" size="0.05" type="capsule"/>
          </body>
        </body>
      </body>
      <geom fromto="0 0 1.70 0 0 1.05" name="torso_geom" size="0.05" type="capsule"/>
      <body name="thigh">
        <joint axis="0 -1 0" name="thigh_joint" pos="0 0 1.05" range="-10 140" type="hinge"/>
        <geom fromto="0 0 1.05 0 0 0.6" name="thigh_geom" size="0.05" type="capsule"/>
        <body name="leg">
          <joint axis="0 -1 0" name="leg_joint" pos="0 0 0.6" range="-120 0" type="hinge"/>
          <geom fromto="0 0 0.6 0 0 0.1" name="leg_geom" size="0.04" type="capsule"/>
          <body name="foot">
            <joint axis="0 -1 0" name="foot_joint" pos="0 0 0.1" range="-45 45" type="hinge"/>
            <geom fromto="-0.0 0 0.1 0.2 0 0.1" name="foot_geom" size="0.06" type="capsule"/>
            <body name="board_right">
              <geom fromto="0.3 0 0.1 -0.9 0 0.1" pos="0 0 -0.1" name="board_geom_right" size="0.05" type="capsule" mass="0.0001"/>
              <body name="board_start">
                <geom fromto="0.3 0 0.11 0.6 0 0.3" pos="0 0 -0.1" name="board_geom_start" size="0.05" type="capsule" mass="0.0001"/>
              </body>
              <body name="board_end">
                <geom fromto="-0.9 0 0.11 -1.2 0 0.3" pos="0 0 -0.1" name="board_geom_end" size="0.05" type="capsule" mass="0.0001"/>
              </body>
            </body>
            
          </body>
        </body>
      </body>
      <!-- copied and then replace thigh->thigh_left, leg->leg_left, foot->foot_right -->
      
      <body name="thigh_left">
        <joint axis="0 1 0" name="thigh_left_joint" pos="0 0 1.05" range="-10 140" type="hinge"/>
        <geom fromto="0 0 1.05 0 0 0.6" name="thigh_left_geom" size="0.05" type="capsule"/>
        <body name="leg_left">
          <joint axis="0 1 0" name="leg_left_joint" pos="0 0 0.6" range="-120 0" type="hinge"/>
          <geom fromto="0 0 0.6 0 0 0.1" name="leg_left_geom" size="0.04" type="capsule"/>
          <body name="foot_left">
            <joint axis="0 1 0" name="foot_left_joint" pos="0 0 0.1" range="-45 45" type="hinge"/>
            <geom fromto="-0.0 0 0.1 -0.2 0 0.1" name="foot_left_geom" size="0.06" type="capsule"/>
          </body>
        </body>
      </body>
    </body>

  </worldbody>
  <equality>
    <weld name="weld_board" body1="board_right" body2="board_left" anchor="0.4 0 0.1" relpos="-1.6 0 0 0 0 0 0"/>
  </equality>
  <actuator>
    <!-- <motor joint="torso_joint" ctrlrange="-100.0 100.0" isctrllimited="true"/>-->
    <motor ctrllimited="true" ctrlrange="-1.0 1.0" gear="100" joint="thigh_joint"/>
    <motor ctrllimited="true" ctrlrange="-1.0 1.0" gear="100" joint="leg_joint"/>
    <motor ctrllimited="true" ctrlrange="-1.0 1.0" gear="100" joint="foot_joint"/>
    <motor ctrllimited="true" ctrlrange="-1.0 1.0" gear="100" joint="thigh_left_joint"/>
    <motor ctrllimited="true" ctrlrange="-1.0 1.0" gear="100" joint="leg_left_joint"/>
    <motor ctrllimited="true" ctrlrange="-1.0 1.0" gear="100" joint="foot_left_joint"/>
    <motor ctrllimited="true" ctrlrange="-1.0 1.0" gear="100" joint="forearm_joint"/>
    <motor ctrllimited="true" ctrlrange="-1.0 1.0" gear="100" joint="forearm_left_joint"/>
    <motor ctrllimited="true" ctrlrange="-1.0 1.0" gear="100" joint="arm_joint"/>
    <motor ctrllimited="true" ctrlrange="-1.0 1.0" gear="100" joint="arm_left_joint"/>

  </actuator>
</mujoco>


